2025-09-09 13:59:21,335 - EXCEPTION - advanced_example - 这是一个测试异常
Traceback (most recent call last):
  File "/Users/guojianli/Documents/python/python-awesome-basic-coding/18-exception-handling/08_logging_exceptions.py", line 278, in test_advanced_logging
    raise ValueError("测试异常")
ValueError: 测试异常
Traceback (most recent call last):
  File "/Users/guojianli/Documents/python/python-awesome-basic-coding/18-exception-handling/08_logging_exceptions.py", line 278, in test_advanced_logging
    raise ValueError("测试异常")
ValueError: 测试异常
2025-09-09 13:59:38,572 - EXCEPTION - advanced_example - 这是一个测试异常
Traceback (most recent call last):
  File "/Users/guojianli/Documents/python/python-awesome-basic-coding/18-exception-handling/08_logging_exceptions.py", line 278, in test_advanced_logging
    raise ValueError("测试异常")
ValueError: 测试异常
Traceback (most recent call last):
  File "/Users/guojianli/Documents/python/python-awesome-basic-coding/18-exception-handling/08_logging_exceptions.py", line 278, in test_advanced_logging
    raise ValueError("测试异常")
ValueError: 测试异常
