2025-09-09 13:59:21,334 - [33mWARNING[0m - 警告信息 - 所有处理器
2025-09-09 13:59:21,334 - [31mERROR[0m - 错误信息 - 所有处理器
2025-09-09 13:59:21,335 - [31mERROR[0m - 这是一个测试异常
Traceback (most recent call last):
  File "/Users/guojianli/Documents/python/python-awesome-basic-coding/18-exception-handling/08_logging_exceptions.py", line 278, in test_advanced_logging
    raise ValueError("测试异常")
ValueError: 测试异常
2025-09-09 13:59:21,337 - [33mWARNING[0m - 批量日志测试 1/10
2025-09-09 13:59:21,337 - [33mWARNING[0m - 批量日志测试 2/10
2025-09-09 13:59:21,338 - [33mWARNING[0m - 批量日志测试 3/10
2025-09-09 13:59:21,339 - [33mWARNING[0m - 批量日志测试 4/10
2025-09-09 13:59:21,339 - [33mWARNING[0m - 批量日志测试 5/10
2025-09-09 13:59:21,339 - [33mWARNING[0m - 批量日志测试 6/10
2025-09-09 13:59:21,339 - [33mWARNING[0m - 批量日志测试 7/10
2025-09-09 13:59:21,339 - [33mWARNING[0m - 批量日志测试 8/10
2025-09-09 13:59:21,339 - [33mWARNING[0m - 批量日志测试 9/10
2025-09-09 13:59:21,339 - [33mWARNING[0m - 批量日志测试 10/10
2025-09-09 13:59:38,572 - [33mWARNING[0m - 警告信息 - 所有处理器
2025-09-09 13:59:38,572 - [31mERROR[0m - 错误信息 - 所有处理器
2025-09-09 13:59:38,572 - [31mERROR[0m - 这是一个测试异常
Traceback (most recent call last):
  File "/Users/guojianli/Documents/python/python-awesome-basic-coding/18-exception-handling/08_logging_exceptions.py", line 278, in test_advanced_logging
    raise ValueError("测试异常")
ValueError: 测试异常
2025-09-09 13:59:38,573 - [33mWARNING[0m - 批量日志测试 1/10
2025-09-09 13:59:38,573 - [33mWARNING[0m - 批量日志测试 2/10
2025-09-09 13:59:38,573 - [33mWARNING[0m - 批量日志测试 3/10
2025-09-09 13:59:38,574 - [33mWARNING[0m - 批量日志测试 4/10
2025-09-09 13:59:38,574 - [33mWARNING[0m - 批量日志测试 5/10
2025-09-09 13:59:38,574 - [33mWARNING[0m - 批量日志测试 6/10
2025-09-09 13:59:38,574 - [33mWARNING[0m - 批量日志测试 7/10
2025-09-09 13:59:38,574 - [33mWARNING[0m - 批量日志测试 8/10
2025-09-09 13:59:38,574 - [33mWARNING[0m - 批量日志测试 9/10
2025-09-09 13:59:38,574 - [33mWARNING[0m - 批量日志测试 10/10
